{
 "cells": [
  {
   "cell_type": "markdown",
   "metadata": {},
   "source": [
    "## Logging"
   ]
  },
  {
   "cell_type": "code",
   "execution_count": 1,
   "metadata": {},
   "outputs": [
    {
     "name": "stderr",
     "output_type": "stream",
     "text": [
      "WARNING:root:This is a warning message\n",
      "ERROR:root:This is an error message\n",
      "CRITICAL:root:This is a critical message\n"
     ]
    }
   ],
   "source": [
    "import logging \n",
    "# 5 different logs levels \n",
    "\n",
    "logging.debug(\"This is a debug message\")\n",
    "logging.info(\"This is an info message\")\n",
    "logging.warning(\"This is a warning message\")\n",
    "logging.error(\"This is an error message\")\n",
    "logging.critical(\"This is a critical message\")\n"
   ]
  },
  {
   "cell_type": "markdown",
   "metadata": {},
   "source": [
    "## Rotating FileHandler"
   ]
  },
  {
   "cell_type": "code",
   "execution_count": 1,
   "metadata": {},
   "outputs": [],
   "source": [
    "import logging\n",
    "from logging.handlers import RotatingFileHandler\n",
    "\n",
    "logger = logging.getLogger(__name__)\n",
    "logger.setLevel(logging.INFO)\n",
    "\n",
    "# roll over after 2KB, and keep backup logs app.log.1, app.log.2 , etc.\n",
    "handler = RotatingFileHandler('app.log', maxBytes=2000, backupCount=5)\n",
    "logger.addHandler(handler)\n",
    "\n",
    "for _ in range(10000):\n",
    "    logger.info('Hello, world!')"
   ]
  },
  {
   "cell_type": "markdown",
   "metadata": {},
   "source": [
    "TimedRotatingFileHandler"
   ]
  },
  {
   "cell_type": "markdown",
   "metadata": {},
   "source": [
    "If your application will be running for a long time, you can use a TimedRotatingFileHandler. This will create a rotating log based on how much time has passed. Possible time conditions for the when parameter are:\n",
    "\n",
    " - second (s)\n",
    " - minute (m)\n",
    " - hour (h)\n",
    " - day (d)\n",
    " - w0-w6 (weekday, 0=Monday)\n",
    " - midnight"
   ]
  },
  {
   "cell_type": "code",
   "execution_count": 3,
   "metadata": {},
   "outputs": [
    {
     "name": "stderr",
     "output_type": "stream",
     "text": [
      "--- Logging error ---\n",
      "Traceback (most recent call last):\n",
      "  File \"c:\\Users\\HP\\anaconda3\\envs\\ge\\Lib\\logging\\handlers.py\", line 74, in emit\n",
      "    self.doRollover()\n",
      "  File \"c:\\Users\\HP\\anaconda3\\envs\\ge\\Lib\\logging\\handlers.py\", line 435, in doRollover\n",
      "    self.rotate(self.baseFilename, dfn)\n",
      "  File \"c:\\Users\\HP\\anaconda3\\envs\\ge\\Lib\\logging\\handlers.py\", line 115, in rotate\n",
      "    os.rename(source, dest)\n",
      "PermissionError: [WinError 32] The process cannot access the file because it is being used by another process: 'd:\\\\full_stack\\\\MyPractice\\\\Python\\\\learning from youtube\\\\Intermediate\\\\logging\\\\timed_test.log' -> 'd:\\\\full_stack\\\\MyPractice\\\\Python\\\\learning from youtube\\\\Intermediate\\\\logging\\\\timed_test.log.2023-09-21_02-48-26'\n",
      "Call stack:\n",
      "  File \"<frozen runpy>\", line 198, in _run_module_as_main\n",
      "  File \"<frozen runpy>\", line 88, in _run_code\n",
      "  File \"c:\\Users\\HP\\anaconda3\\envs\\ge\\Lib\\site-packages\\ipykernel_launcher.py\", line 17, in <module>\n",
      "    app.launch_new_instance()\n",
      "  File \"c:\\Users\\HP\\anaconda3\\envs\\ge\\Lib\\site-packages\\traitlets\\config\\application.py\", line 1043, in launch_instance\n",
      "    app.start()\n",
      "  File \"c:\\Users\\HP\\anaconda3\\envs\\ge\\Lib\\site-packages\\ipykernel\\kernelapp.py\", line 712, in start\n",
      "    self.io_loop.start()\n",
      "  File \"c:\\Users\\HP\\anaconda3\\envs\\ge\\Lib\\site-packages\\tornado\\platform\\asyncio.py\", line 215, in start\n",
      "    self.asyncio_loop.run_forever()\n",
      "  File \"c:\\Users\\HP\\anaconda3\\envs\\ge\\Lib\\asyncio\\base_events.py\", line 607, in run_forever\n",
      "    self._run_once()\n",
      "  File \"c:\\Users\\HP\\anaconda3\\envs\\ge\\Lib\\asyncio\\base_events.py\", line 1922, in _run_once\n",
      "    handle._run()\n",
      "  File \"c:\\Users\\HP\\anaconda3\\envs\\ge\\Lib\\asyncio\\events.py\", line 80, in _run\n",
      "    self._context.run(self._callback, *self._args)\n",
      "  File \"c:\\Users\\HP\\anaconda3\\envs\\ge\\Lib\\site-packages\\ipykernel\\kernelbase.py\", line 510, in dispatch_queue\n",
      "    await self.process_one()\n",
      "  File \"c:\\Users\\HP\\anaconda3\\envs\\ge\\Lib\\site-packages\\ipykernel\\kernelbase.py\", line 499, in process_one\n",
      "    await dispatch(*args)\n",
      "  File \"c:\\Users\\HP\\anaconda3\\envs\\ge\\Lib\\site-packages\\ipykernel\\kernelbase.py\", line 406, in dispatch_shell\n",
      "    await result\n",
      "  File \"c:\\Users\\HP\\anaconda3\\envs\\ge\\Lib\\site-packages\\ipykernel\\kernelbase.py\", line 730, in execute_request\n",
      "    reply_content = await reply_content\n",
      "  File \"c:\\Users\\HP\\anaconda3\\envs\\ge\\Lib\\site-packages\\ipykernel\\ipkernel.py\", line 383, in do_execute\n",
      "    res = shell.run_cell(\n",
      "  File \"c:\\Users\\HP\\anaconda3\\envs\\ge\\Lib\\site-packages\\ipykernel\\zmqshell.py\", line 528, in run_cell\n",
      "    return super().run_cell(*args, **kwargs)\n",
      "  File \"c:\\Users\\HP\\anaconda3\\envs\\ge\\Lib\\site-packages\\IPython\\core\\interactiveshell.py\", line 3009, in run_cell\n",
      "    result = self._run_cell(\n",
      "  File \"c:\\Users\\HP\\anaconda3\\envs\\ge\\Lib\\site-packages\\IPython\\core\\interactiveshell.py\", line 3064, in _run_cell\n",
      "    result = runner(coro)\n",
      "  File \"c:\\Users\\HP\\anaconda3\\envs\\ge\\Lib\\site-packages\\IPython\\core\\async_helpers.py\", line 129, in _pseudo_sync_runner\n",
      "    coro.send(None)\n",
      "  File \"c:\\Users\\HP\\anaconda3\\envs\\ge\\Lib\\site-packages\\IPython\\core\\interactiveshell.py\", line 3269, in run_cell_async\n",
      "    has_raised = await self.run_ast_nodes(code_ast.body, cell_name,\n",
      "  File \"c:\\Users\\HP\\anaconda3\\envs\\ge\\Lib\\site-packages\\IPython\\core\\interactiveshell.py\", line 3448, in run_ast_nodes\n",
      "    if await self.run_code(code, result, async_=asy):\n",
      "  File \"c:\\Users\\HP\\anaconda3\\envs\\ge\\Lib\\site-packages\\IPython\\core\\interactiveshell.py\", line 3508, in run_code\n",
      "    exec(code_obj, self.user_global_ns, self.user_ns)\n",
      "  File \"C:\\Users\\HP\\AppData\\Local\\Temp\\ipykernel_17184\\2897584328.py\", line 13, in <module>\n",
      "    logger.info('hey')\n",
      "Message: 'hey'\n",
      "Arguments: ()\n",
      "--- Logging error ---\n",
      "Traceback (most recent call last):\n",
      "  File \"c:\\Users\\HP\\anaconda3\\envs\\ge\\Lib\\logging\\handlers.py\", line 74, in emit\n",
      "    self.doRollover()\n",
      "  File \"c:\\Users\\HP\\anaconda3\\envs\\ge\\Lib\\logging\\handlers.py\", line 435, in doRollover\n",
      "    self.rotate(self.baseFilename, dfn)\n",
      "  File \"c:\\Users\\HP\\anaconda3\\envs\\ge\\Lib\\logging\\handlers.py\", line 115, in rotate\n",
      "    os.rename(source, dest)\n",
      "PermissionError: [WinError 32] The process cannot access the file because it is being used by another process: 'd:\\\\full_stack\\\\MyPractice\\\\Python\\\\learning from youtube\\\\Intermediate\\\\logging\\\\timed_test.log' -> 'd:\\\\full_stack\\\\MyPractice\\\\Python\\\\learning from youtube\\\\Intermediate\\\\logging\\\\timed_test.log.2023-09-21_02-49-38'\n",
      "Call stack:\n",
      "  File \"<frozen runpy>\", line 198, in _run_module_as_main\n",
      "  File \"<frozen runpy>\", line 88, in _run_code\n",
      "  File \"c:\\Users\\HP\\anaconda3\\envs\\ge\\Lib\\site-packages\\ipykernel_launcher.py\", line 17, in <module>\n",
      "    app.launch_new_instance()\n",
      "  File \"c:\\Users\\HP\\anaconda3\\envs\\ge\\Lib\\site-packages\\traitlets\\config\\application.py\", line 1043, in launch_instance\n",
      "    app.start()\n",
      "  File \"c:\\Users\\HP\\anaconda3\\envs\\ge\\Lib\\site-packages\\ipykernel\\kernelapp.py\", line 712, in start\n",
      "    self.io_loop.start()\n",
      "  File \"c:\\Users\\HP\\anaconda3\\envs\\ge\\Lib\\site-packages\\tornado\\platform\\asyncio.py\", line 215, in start\n",
      "    self.asyncio_loop.run_forever()\n",
      "  File \"c:\\Users\\HP\\anaconda3\\envs\\ge\\Lib\\asyncio\\base_events.py\", line 607, in run_forever\n",
      "    self._run_once()\n",
      "  File \"c:\\Users\\HP\\anaconda3\\envs\\ge\\Lib\\asyncio\\base_events.py\", line 1922, in _run_once\n",
      "    handle._run()\n",
      "  File \"c:\\Users\\HP\\anaconda3\\envs\\ge\\Lib\\asyncio\\events.py\", line 80, in _run\n",
      "    self._context.run(self._callback, *self._args)\n",
      "  File \"c:\\Users\\HP\\anaconda3\\envs\\ge\\Lib\\site-packages\\ipykernel\\kernelbase.py\", line 510, in dispatch_queue\n",
      "    await self.process_one()\n",
      "  File \"c:\\Users\\HP\\anaconda3\\envs\\ge\\Lib\\site-packages\\ipykernel\\kernelbase.py\", line 499, in process_one\n",
      "    await dispatch(*args)\n",
      "  File \"c:\\Users\\HP\\anaconda3\\envs\\ge\\Lib\\site-packages\\ipykernel\\kernelbase.py\", line 406, in dispatch_shell\n",
      "    await result\n",
      "  File \"c:\\Users\\HP\\anaconda3\\envs\\ge\\Lib\\site-packages\\ipykernel\\kernelbase.py\", line 730, in execute_request\n",
      "    reply_content = await reply_content\n",
      "  File \"c:\\Users\\HP\\anaconda3\\envs\\ge\\Lib\\site-packages\\ipykernel\\ipkernel.py\", line 383, in do_execute\n",
      "    res = shell.run_cell(\n",
      "  File \"c:\\Users\\HP\\anaconda3\\envs\\ge\\Lib\\site-packages\\ipykernel\\zmqshell.py\", line 528, in run_cell\n",
      "    return super().run_cell(*args, **kwargs)\n",
      "  File \"c:\\Users\\HP\\anaconda3\\envs\\ge\\Lib\\site-packages\\IPython\\core\\interactiveshell.py\", line 3009, in run_cell\n",
      "    result = self._run_cell(\n",
      "  File \"c:\\Users\\HP\\anaconda3\\envs\\ge\\Lib\\site-packages\\IPython\\core\\interactiveshell.py\", line 3064, in _run_cell\n",
      "    result = runner(coro)\n",
      "  File \"c:\\Users\\HP\\anaconda3\\envs\\ge\\Lib\\site-packages\\IPython\\core\\async_helpers.py\", line 129, in _pseudo_sync_runner\n",
      "    coro.send(None)\n",
      "  File \"c:\\Users\\HP\\anaconda3\\envs\\ge\\Lib\\site-packages\\IPython\\core\\interactiveshell.py\", line 3269, in run_cell_async\n",
      "    has_raised = await self.run_ast_nodes(code_ast.body, cell_name,\n",
      "  File \"c:\\Users\\HP\\anaconda3\\envs\\ge\\Lib\\site-packages\\IPython\\core\\interactiveshell.py\", line 3448, in run_ast_nodes\n",
      "    if await self.run_code(code, result, async_=asy):\n",
      "  File \"c:\\Users\\HP\\anaconda3\\envs\\ge\\Lib\\site-packages\\IPython\\core\\interactiveshell.py\", line 3508, in run_code\n",
      "    exec(code_obj, self.user_global_ns, self.user_ns)\n",
      "  File \"C:\\Users\\HP\\AppData\\Local\\Temp\\ipykernel_17184\\2897584328.py\", line 13, in <module>\n",
      "    logger.info('hey')\n",
      "Message: 'hey'\n",
      "Arguments: ()\n",
      "--- Logging error ---\n",
      "Traceback (most recent call last):\n",
      "  File \"c:\\Users\\HP\\anaconda3\\envs\\ge\\Lib\\logging\\handlers.py\", line 74, in emit\n",
      "    self.doRollover()\n",
      "  File \"c:\\Users\\HP\\anaconda3\\envs\\ge\\Lib\\logging\\handlers.py\", line 435, in doRollover\n",
      "    self.rotate(self.baseFilename, dfn)\n",
      "  File \"c:\\Users\\HP\\anaconda3\\envs\\ge\\Lib\\logging\\handlers.py\", line 115, in rotate\n",
      "    os.rename(source, dest)\n",
      "PermissionError: [WinError 32] The process cannot access the file because it is being used by another process: 'd:\\\\full_stack\\\\MyPractice\\\\Python\\\\learning from youtube\\\\Intermediate\\\\logging\\\\timed_test.log' -> 'd:\\\\full_stack\\\\MyPractice\\\\Python\\\\learning from youtube\\\\Intermediate\\\\logging\\\\timed_test.log.2023-09-21_02-48-26'\n",
      "Call stack:\n",
      "  File \"<frozen runpy>\", line 198, in _run_module_as_main\n",
      "  File \"<frozen runpy>\", line 88, in _run_code\n",
      "  File \"c:\\Users\\HP\\anaconda3\\envs\\ge\\Lib\\site-packages\\ipykernel_launcher.py\", line 17, in <module>\n",
      "    app.launch_new_instance()\n",
      "  File \"c:\\Users\\HP\\anaconda3\\envs\\ge\\Lib\\site-packages\\traitlets\\config\\application.py\", line 1043, in launch_instance\n",
      "    app.start()\n",
      "  File \"c:\\Users\\HP\\anaconda3\\envs\\ge\\Lib\\site-packages\\ipykernel\\kernelapp.py\", line 712, in start\n",
      "    self.io_loop.start()\n",
      "  File \"c:\\Users\\HP\\anaconda3\\envs\\ge\\Lib\\site-packages\\tornado\\platform\\asyncio.py\", line 215, in start\n",
      "    self.asyncio_loop.run_forever()\n",
      "  File \"c:\\Users\\HP\\anaconda3\\envs\\ge\\Lib\\asyncio\\base_events.py\", line 607, in run_forever\n",
      "    self._run_once()\n",
      "  File \"c:\\Users\\HP\\anaconda3\\envs\\ge\\Lib\\asyncio\\base_events.py\", line 1922, in _run_once\n",
      "    handle._run()\n",
      "  File \"c:\\Users\\HP\\anaconda3\\envs\\ge\\Lib\\asyncio\\events.py\", line 80, in _run\n",
      "    self._context.run(self._callback, *self._args)\n",
      "  File \"c:\\Users\\HP\\anaconda3\\envs\\ge\\Lib\\site-packages\\ipykernel\\kernelbase.py\", line 510, in dispatch_queue\n",
      "    await self.process_one()\n",
      "  File \"c:\\Users\\HP\\anaconda3\\envs\\ge\\Lib\\site-packages\\ipykernel\\kernelbase.py\", line 499, in process_one\n",
      "    await dispatch(*args)\n",
      "  File \"c:\\Users\\HP\\anaconda3\\envs\\ge\\Lib\\site-packages\\ipykernel\\kernelbase.py\", line 406, in dispatch_shell\n",
      "    await result\n",
      "  File \"c:\\Users\\HP\\anaconda3\\envs\\ge\\Lib\\site-packages\\ipykernel\\kernelbase.py\", line 730, in execute_request\n",
      "    reply_content = await reply_content\n",
      "  File \"c:\\Users\\HP\\anaconda3\\envs\\ge\\Lib\\site-packages\\ipykernel\\ipkernel.py\", line 383, in do_execute\n",
      "    res = shell.run_cell(\n",
      "  File \"c:\\Users\\HP\\anaconda3\\envs\\ge\\Lib\\site-packages\\ipykernel\\zmqshell.py\", line 528, in run_cell\n",
      "    return super().run_cell(*args, **kwargs)\n",
      "  File \"c:\\Users\\HP\\anaconda3\\envs\\ge\\Lib\\site-packages\\IPython\\core\\interactiveshell.py\", line 3009, in run_cell\n",
      "    result = self._run_cell(\n",
      "  File \"c:\\Users\\HP\\anaconda3\\envs\\ge\\Lib\\site-packages\\IPython\\core\\interactiveshell.py\", line 3064, in _run_cell\n",
      "    result = runner(coro)\n",
      "  File \"c:\\Users\\HP\\anaconda3\\envs\\ge\\Lib\\site-packages\\IPython\\core\\async_helpers.py\", line 129, in _pseudo_sync_runner\n",
      "    coro.send(None)\n",
      "  File \"c:\\Users\\HP\\anaconda3\\envs\\ge\\Lib\\site-packages\\IPython\\core\\interactiveshell.py\", line 3269, in run_cell_async\n",
      "    has_raised = await self.run_ast_nodes(code_ast.body, cell_name,\n",
      "  File \"c:\\Users\\HP\\anaconda3\\envs\\ge\\Lib\\site-packages\\IPython\\core\\interactiveshell.py\", line 3448, in run_ast_nodes\n",
      "    if await self.run_code(code, result, async_=asy):\n",
      "  File \"c:\\Users\\HP\\anaconda3\\envs\\ge\\Lib\\site-packages\\IPython\\core\\interactiveshell.py\", line 3508, in run_code\n",
      "    exec(code_obj, self.user_global_ns, self.user_ns)\n",
      "  File \"C:\\Users\\HP\\AppData\\Local\\Temp\\ipykernel_17184\\2897584328.py\", line 13, in <module>\n",
      "    logger.info('hey')\n",
      "Message: 'hey'\n",
      "Arguments: ()\n",
      "--- Logging error ---\n",
      "Traceback (most recent call last):\n",
      "  File \"c:\\Users\\HP\\anaconda3\\envs\\ge\\Lib\\logging\\handlers.py\", line 74, in emit\n",
      "    self.doRollover()\n",
      "  File \"c:\\Users\\HP\\anaconda3\\envs\\ge\\Lib\\logging\\handlers.py\", line 435, in doRollover\n",
      "    self.rotate(self.baseFilename, dfn)\n",
      "  File \"c:\\Users\\HP\\anaconda3\\envs\\ge\\Lib\\logging\\handlers.py\", line 115, in rotate\n",
      "    os.rename(source, dest)\n",
      "PermissionError: [WinError 32] The process cannot access the file because it is being used by another process: 'd:\\\\full_stack\\\\MyPractice\\\\Python\\\\learning from youtube\\\\Intermediate\\\\logging\\\\timed_test.log' -> 'd:\\\\full_stack\\\\MyPractice\\\\Python\\\\learning from youtube\\\\Intermediate\\\\logging\\\\timed_test.log.2023-09-21_02-49-38'\n",
      "Call stack:\n",
      "  File \"<frozen runpy>\", line 198, in _run_module_as_main\n",
      "  File \"<frozen runpy>\", line 88, in _run_code\n",
      "  File \"c:\\Users\\HP\\anaconda3\\envs\\ge\\Lib\\site-packages\\ipykernel_launcher.py\", line 17, in <module>\n",
      "    app.launch_new_instance()\n",
      "  File \"c:\\Users\\HP\\anaconda3\\envs\\ge\\Lib\\site-packages\\traitlets\\config\\application.py\", line 1043, in launch_instance\n",
      "    app.start()\n",
      "  File \"c:\\Users\\HP\\anaconda3\\envs\\ge\\Lib\\site-packages\\ipykernel\\kernelapp.py\", line 712, in start\n",
      "    self.io_loop.start()\n",
      "  File \"c:\\Users\\HP\\anaconda3\\envs\\ge\\Lib\\site-packages\\tornado\\platform\\asyncio.py\", line 215, in start\n",
      "    self.asyncio_loop.run_forever()\n",
      "  File \"c:\\Users\\HP\\anaconda3\\envs\\ge\\Lib\\asyncio\\base_events.py\", line 607, in run_forever\n",
      "    self._run_once()\n",
      "  File \"c:\\Users\\HP\\anaconda3\\envs\\ge\\Lib\\asyncio\\base_events.py\", line 1922, in _run_once\n",
      "    handle._run()\n",
      "  File \"c:\\Users\\HP\\anaconda3\\envs\\ge\\Lib\\asyncio\\events.py\", line 80, in _run\n",
      "    self._context.run(self._callback, *self._args)\n",
      "  File \"c:\\Users\\HP\\anaconda3\\envs\\ge\\Lib\\site-packages\\ipykernel\\kernelbase.py\", line 510, in dispatch_queue\n",
      "    await self.process_one()\n",
      "  File \"c:\\Users\\HP\\anaconda3\\envs\\ge\\Lib\\site-packages\\ipykernel\\kernelbase.py\", line 499, in process_one\n",
      "    await dispatch(*args)\n",
      "  File \"c:\\Users\\HP\\anaconda3\\envs\\ge\\Lib\\site-packages\\ipykernel\\kernelbase.py\", line 406, in dispatch_shell\n",
      "    await result\n",
      "  File \"c:\\Users\\HP\\anaconda3\\envs\\ge\\Lib\\site-packages\\ipykernel\\kernelbase.py\", line 730, in execute_request\n",
      "    reply_content = await reply_content\n",
      "  File \"c:\\Users\\HP\\anaconda3\\envs\\ge\\Lib\\site-packages\\ipykernel\\ipkernel.py\", line 383, in do_execute\n",
      "    res = shell.run_cell(\n",
      "  File \"c:\\Users\\HP\\anaconda3\\envs\\ge\\Lib\\site-packages\\ipykernel\\zmqshell.py\", line 528, in run_cell\n",
      "    return super().run_cell(*args, **kwargs)\n",
      "  File \"c:\\Users\\HP\\anaconda3\\envs\\ge\\Lib\\site-packages\\IPython\\core\\interactiveshell.py\", line 3009, in run_cell\n",
      "    result = self._run_cell(\n",
      "  File \"c:\\Users\\HP\\anaconda3\\envs\\ge\\Lib\\site-packages\\IPython\\core\\interactiveshell.py\", line 3064, in _run_cell\n",
      "    result = runner(coro)\n",
      "  File \"c:\\Users\\HP\\anaconda3\\envs\\ge\\Lib\\site-packages\\IPython\\core\\async_helpers.py\", line 129, in _pseudo_sync_runner\n",
      "    coro.send(None)\n",
      "  File \"c:\\Users\\HP\\anaconda3\\envs\\ge\\Lib\\site-packages\\IPython\\core\\interactiveshell.py\", line 3269, in run_cell_async\n",
      "    has_raised = await self.run_ast_nodes(code_ast.body, cell_name,\n",
      "  File \"c:\\Users\\HP\\anaconda3\\envs\\ge\\Lib\\site-packages\\IPython\\core\\interactiveshell.py\", line 3448, in run_ast_nodes\n",
      "    if await self.run_code(code, result, async_=asy):\n",
      "  File \"c:\\Users\\HP\\anaconda3\\envs\\ge\\Lib\\site-packages\\IPython\\core\\interactiveshell.py\", line 3508, in run_code\n",
      "    exec(code_obj, self.user_global_ns, self.user_ns)\n",
      "  File \"C:\\Users\\HP\\AppData\\Local\\Temp\\ipykernel_17184\\2897584328.py\", line 13, in <module>\n",
      "    logger.info('hey')\n",
      "Message: 'hey'\n",
      "Arguments: ()\n",
      "--- Logging error ---\n",
      "Traceback (most recent call last):\n",
      "  File \"c:\\Users\\HP\\anaconda3\\envs\\ge\\Lib\\logging\\handlers.py\", line 74, in emit\n",
      "    self.doRollover()\n",
      "  File \"c:\\Users\\HP\\anaconda3\\envs\\ge\\Lib\\logging\\handlers.py\", line 435, in doRollover\n",
      "    self.rotate(self.baseFilename, dfn)\n",
      "  File \"c:\\Users\\HP\\anaconda3\\envs\\ge\\Lib\\logging\\handlers.py\", line 115, in rotate\n",
      "    os.rename(source, dest)\n",
      "PermissionError: [WinError 32] The process cannot access the file because it is being used by another process: 'd:\\\\full_stack\\\\MyPractice\\\\Python\\\\learning from youtube\\\\Intermediate\\\\logging\\\\timed_test.log' -> 'd:\\\\full_stack\\\\MyPractice\\\\Python\\\\learning from youtube\\\\Intermediate\\\\logging\\\\timed_test.log.2023-09-21_02-48-26'\n",
      "Call stack:\n",
      "  File \"<frozen runpy>\", line 198, in _run_module_as_main\n",
      "  File \"<frozen runpy>\", line 88, in _run_code\n",
      "  File \"c:\\Users\\HP\\anaconda3\\envs\\ge\\Lib\\site-packages\\ipykernel_launcher.py\", line 17, in <module>\n",
      "    app.launch_new_instance()\n",
      "  File \"c:\\Users\\HP\\anaconda3\\envs\\ge\\Lib\\site-packages\\traitlets\\config\\application.py\", line 1043, in launch_instance\n",
      "    app.start()\n",
      "  File \"c:\\Users\\HP\\anaconda3\\envs\\ge\\Lib\\site-packages\\ipykernel\\kernelapp.py\", line 712, in start\n",
      "    self.io_loop.start()\n",
      "  File \"c:\\Users\\HP\\anaconda3\\envs\\ge\\Lib\\site-packages\\tornado\\platform\\asyncio.py\", line 215, in start\n",
      "    self.asyncio_loop.run_forever()\n",
      "  File \"c:\\Users\\HP\\anaconda3\\envs\\ge\\Lib\\asyncio\\base_events.py\", line 607, in run_forever\n",
      "    self._run_once()\n",
      "  File \"c:\\Users\\HP\\anaconda3\\envs\\ge\\Lib\\asyncio\\base_events.py\", line 1922, in _run_once\n",
      "    handle._run()\n",
      "  File \"c:\\Users\\HP\\anaconda3\\envs\\ge\\Lib\\asyncio\\events.py\", line 80, in _run\n",
      "    self._context.run(self._callback, *self._args)\n",
      "  File \"c:\\Users\\HP\\anaconda3\\envs\\ge\\Lib\\site-packages\\ipykernel\\kernelbase.py\", line 510, in dispatch_queue\n",
      "    await self.process_one()\n",
      "  File \"c:\\Users\\HP\\anaconda3\\envs\\ge\\Lib\\site-packages\\ipykernel\\kernelbase.py\", line 499, in process_one\n",
      "    await dispatch(*args)\n",
      "  File \"c:\\Users\\HP\\anaconda3\\envs\\ge\\Lib\\site-packages\\ipykernel\\kernelbase.py\", line 406, in dispatch_shell\n",
      "    await result\n",
      "  File \"c:\\Users\\HP\\anaconda3\\envs\\ge\\Lib\\site-packages\\ipykernel\\kernelbase.py\", line 730, in execute_request\n",
      "    reply_content = await reply_content\n",
      "  File \"c:\\Users\\HP\\anaconda3\\envs\\ge\\Lib\\site-packages\\ipykernel\\ipkernel.py\", line 383, in do_execute\n",
      "    res = shell.run_cell(\n",
      "  File \"c:\\Users\\HP\\anaconda3\\envs\\ge\\Lib\\site-packages\\ipykernel\\zmqshell.py\", line 528, in run_cell\n",
      "    return super().run_cell(*args, **kwargs)\n",
      "  File \"c:\\Users\\HP\\anaconda3\\envs\\ge\\Lib\\site-packages\\IPython\\core\\interactiveshell.py\", line 3009, in run_cell\n",
      "    result = self._run_cell(\n",
      "  File \"c:\\Users\\HP\\anaconda3\\envs\\ge\\Lib\\site-packages\\IPython\\core\\interactiveshell.py\", line 3064, in _run_cell\n",
      "    result = runner(coro)\n",
      "  File \"c:\\Users\\HP\\anaconda3\\envs\\ge\\Lib\\site-packages\\IPython\\core\\async_helpers.py\", line 129, in _pseudo_sync_runner\n",
      "    coro.send(None)\n",
      "  File \"c:\\Users\\HP\\anaconda3\\envs\\ge\\Lib\\site-packages\\IPython\\core\\interactiveshell.py\", line 3269, in run_cell_async\n",
      "    has_raised = await self.run_ast_nodes(code_ast.body, cell_name,\n",
      "  File \"c:\\Users\\HP\\anaconda3\\envs\\ge\\Lib\\site-packages\\IPython\\core\\interactiveshell.py\", line 3448, in run_ast_nodes\n",
      "    if await self.run_code(code, result, async_=asy):\n",
      "  File \"c:\\Users\\HP\\anaconda3\\envs\\ge\\Lib\\site-packages\\IPython\\core\\interactiveshell.py\", line 3508, in run_code\n",
      "    exec(code_obj, self.user_global_ns, self.user_ns)\n",
      "  File \"C:\\Users\\HP\\AppData\\Local\\Temp\\ipykernel_17184\\2897584328.py\", line 13, in <module>\n",
      "    logger.info('hey')\n",
      "Message: 'hey'\n",
      "Arguments: ()\n",
      "--- Logging error ---\n",
      "Traceback (most recent call last):\n",
      "  File \"c:\\Users\\HP\\anaconda3\\envs\\ge\\Lib\\logging\\handlers.py\", line 74, in emit\n",
      "    self.doRollover()\n",
      "  File \"c:\\Users\\HP\\anaconda3\\envs\\ge\\Lib\\logging\\handlers.py\", line 435, in doRollover\n",
      "    self.rotate(self.baseFilename, dfn)\n",
      "  File \"c:\\Users\\HP\\anaconda3\\envs\\ge\\Lib\\logging\\handlers.py\", line 115, in rotate\n",
      "    os.rename(source, dest)\n",
      "PermissionError: [WinError 32] The process cannot access the file because it is being used by another process: 'd:\\\\full_stack\\\\MyPractice\\\\Python\\\\learning from youtube\\\\Intermediate\\\\logging\\\\timed_test.log' -> 'd:\\\\full_stack\\\\MyPractice\\\\Python\\\\learning from youtube\\\\Intermediate\\\\logging\\\\timed_test.log.2023-09-21_02-49-38'\n",
      "Call stack:\n",
      "  File \"<frozen runpy>\", line 198, in _run_module_as_main\n",
      "  File \"<frozen runpy>\", line 88, in _run_code\n",
      "  File \"c:\\Users\\HP\\anaconda3\\envs\\ge\\Lib\\site-packages\\ipykernel_launcher.py\", line 17, in <module>\n",
      "    app.launch_new_instance()\n",
      "  File \"c:\\Users\\HP\\anaconda3\\envs\\ge\\Lib\\site-packages\\traitlets\\config\\application.py\", line 1043, in launch_instance\n",
      "    app.start()\n",
      "  File \"c:\\Users\\HP\\anaconda3\\envs\\ge\\Lib\\site-packages\\ipykernel\\kernelapp.py\", line 712, in start\n",
      "    self.io_loop.start()\n",
      "  File \"c:\\Users\\HP\\anaconda3\\envs\\ge\\Lib\\site-packages\\tornado\\platform\\asyncio.py\", line 215, in start\n",
      "    self.asyncio_loop.run_forever()\n",
      "  File \"c:\\Users\\HP\\anaconda3\\envs\\ge\\Lib\\asyncio\\base_events.py\", line 607, in run_forever\n",
      "    self._run_once()\n",
      "  File \"c:\\Users\\HP\\anaconda3\\envs\\ge\\Lib\\asyncio\\base_events.py\", line 1922, in _run_once\n",
      "    handle._run()\n",
      "  File \"c:\\Users\\HP\\anaconda3\\envs\\ge\\Lib\\asyncio\\events.py\", line 80, in _run\n",
      "    self._context.run(self._callback, *self._args)\n",
      "  File \"c:\\Users\\HP\\anaconda3\\envs\\ge\\Lib\\site-packages\\ipykernel\\kernelbase.py\", line 510, in dispatch_queue\n",
      "    await self.process_one()\n",
      "  File \"c:\\Users\\HP\\anaconda3\\envs\\ge\\Lib\\site-packages\\ipykernel\\kernelbase.py\", line 499, in process_one\n",
      "    await dispatch(*args)\n",
      "  File \"c:\\Users\\HP\\anaconda3\\envs\\ge\\Lib\\site-packages\\ipykernel\\kernelbase.py\", line 406, in dispatch_shell\n",
      "    await result\n",
      "  File \"c:\\Users\\HP\\anaconda3\\envs\\ge\\Lib\\site-packages\\ipykernel\\kernelbase.py\", line 730, in execute_request\n",
      "    reply_content = await reply_content\n",
      "  File \"c:\\Users\\HP\\anaconda3\\envs\\ge\\Lib\\site-packages\\ipykernel\\ipkernel.py\", line 383, in do_execute\n",
      "    res = shell.run_cell(\n",
      "  File \"c:\\Users\\HP\\anaconda3\\envs\\ge\\Lib\\site-packages\\ipykernel\\zmqshell.py\", line 528, in run_cell\n",
      "    return super().run_cell(*args, **kwargs)\n",
      "  File \"c:\\Users\\HP\\anaconda3\\envs\\ge\\Lib\\site-packages\\IPython\\core\\interactiveshell.py\", line 3009, in run_cell\n",
      "    result = self._run_cell(\n",
      "  File \"c:\\Users\\HP\\anaconda3\\envs\\ge\\Lib\\site-packages\\IPython\\core\\interactiveshell.py\", line 3064, in _run_cell\n",
      "    result = runner(coro)\n",
      "  File \"c:\\Users\\HP\\anaconda3\\envs\\ge\\Lib\\site-packages\\IPython\\core\\async_helpers.py\", line 129, in _pseudo_sync_runner\n",
      "    coro.send(None)\n",
      "  File \"c:\\Users\\HP\\anaconda3\\envs\\ge\\Lib\\site-packages\\IPython\\core\\interactiveshell.py\", line 3269, in run_cell_async\n",
      "    has_raised = await self.run_ast_nodes(code_ast.body, cell_name,\n",
      "  File \"c:\\Users\\HP\\anaconda3\\envs\\ge\\Lib\\site-packages\\IPython\\core\\interactiveshell.py\", line 3448, in run_ast_nodes\n",
      "    if await self.run_code(code, result, async_=asy):\n",
      "  File \"c:\\Users\\HP\\anaconda3\\envs\\ge\\Lib\\site-packages\\IPython\\core\\interactiveshell.py\", line 3508, in run_code\n",
      "    exec(code_obj, self.user_global_ns, self.user_ns)\n",
      "  File \"C:\\Users\\HP\\AppData\\Local\\Temp\\ipykernel_17184\\2897584328.py\", line 13, in <module>\n",
      "    logger.info('hey')\n",
      "Message: 'hey'\n",
      "Arguments: ()\n",
      "--- Logging error ---\n",
      "Traceback (most recent call last):\n",
      "  File \"c:\\Users\\HP\\anaconda3\\envs\\ge\\Lib\\logging\\handlers.py\", line 74, in emit\n",
      "    self.doRollover()\n",
      "  File \"c:\\Users\\HP\\anaconda3\\envs\\ge\\Lib\\logging\\handlers.py\", line 435, in doRollover\n",
      "    self.rotate(self.baseFilename, dfn)\n",
      "  File \"c:\\Users\\HP\\anaconda3\\envs\\ge\\Lib\\logging\\handlers.py\", line 115, in rotate\n",
      "    os.rename(source, dest)\n",
      "PermissionError: [WinError 32] The process cannot access the file because it is being used by another process: 'd:\\\\full_stack\\\\MyPractice\\\\Python\\\\learning from youtube\\\\Intermediate\\\\logging\\\\timed_test.log' -> 'd:\\\\full_stack\\\\MyPractice\\\\Python\\\\learning from youtube\\\\Intermediate\\\\logging\\\\timed_test.log.2023-09-21_02-48-26'\n",
      "Call stack:\n",
      "  File \"<frozen runpy>\", line 198, in _run_module_as_main\n",
      "  File \"<frozen runpy>\", line 88, in _run_code\n",
      "  File \"c:\\Users\\HP\\anaconda3\\envs\\ge\\Lib\\site-packages\\ipykernel_launcher.py\", line 17, in <module>\n",
      "    app.launch_new_instance()\n",
      "  File \"c:\\Users\\HP\\anaconda3\\envs\\ge\\Lib\\site-packages\\traitlets\\config\\application.py\", line 1043, in launch_instance\n",
      "    app.start()\n",
      "  File \"c:\\Users\\HP\\anaconda3\\envs\\ge\\Lib\\site-packages\\ipykernel\\kernelapp.py\", line 712, in start\n",
      "    self.io_loop.start()\n",
      "  File \"c:\\Users\\HP\\anaconda3\\envs\\ge\\Lib\\site-packages\\tornado\\platform\\asyncio.py\", line 215, in start\n",
      "    self.asyncio_loop.run_forever()\n",
      "  File \"c:\\Users\\HP\\anaconda3\\envs\\ge\\Lib\\asyncio\\base_events.py\", line 607, in run_forever\n",
      "    self._run_once()\n",
      "  File \"c:\\Users\\HP\\anaconda3\\envs\\ge\\Lib\\asyncio\\base_events.py\", line 1922, in _run_once\n",
      "    handle._run()\n",
      "  File \"c:\\Users\\HP\\anaconda3\\envs\\ge\\Lib\\asyncio\\events.py\", line 80, in _run\n",
      "    self._context.run(self._callback, *self._args)\n",
      "  File \"c:\\Users\\HP\\anaconda3\\envs\\ge\\Lib\\site-packages\\ipykernel\\kernelbase.py\", line 510, in dispatch_queue\n",
      "    await self.process_one()\n",
      "  File \"c:\\Users\\HP\\anaconda3\\envs\\ge\\Lib\\site-packages\\ipykernel\\kernelbase.py\", line 499, in process_one\n",
      "    await dispatch(*args)\n",
      "  File \"c:\\Users\\HP\\anaconda3\\envs\\ge\\Lib\\site-packages\\ipykernel\\kernelbase.py\", line 406, in dispatch_shell\n",
      "    await result\n",
      "  File \"c:\\Users\\HP\\anaconda3\\envs\\ge\\Lib\\site-packages\\ipykernel\\kernelbase.py\", line 730, in execute_request\n",
      "    reply_content = await reply_content\n",
      "  File \"c:\\Users\\HP\\anaconda3\\envs\\ge\\Lib\\site-packages\\ipykernel\\ipkernel.py\", line 383, in do_execute\n",
      "    res = shell.run_cell(\n",
      "  File \"c:\\Users\\HP\\anaconda3\\envs\\ge\\Lib\\site-packages\\ipykernel\\zmqshell.py\", line 528, in run_cell\n",
      "    return super().run_cell(*args, **kwargs)\n",
      "  File \"c:\\Users\\HP\\anaconda3\\envs\\ge\\Lib\\site-packages\\IPython\\core\\interactiveshell.py\", line 3009, in run_cell\n",
      "    result = self._run_cell(\n",
      "  File \"c:\\Users\\HP\\anaconda3\\envs\\ge\\Lib\\site-packages\\IPython\\core\\interactiveshell.py\", line 3064, in _run_cell\n",
      "    result = runner(coro)\n",
      "  File \"c:\\Users\\HP\\anaconda3\\envs\\ge\\Lib\\site-packages\\IPython\\core\\async_helpers.py\", line 129, in _pseudo_sync_runner\n",
      "    coro.send(None)\n",
      "  File \"c:\\Users\\HP\\anaconda3\\envs\\ge\\Lib\\site-packages\\IPython\\core\\interactiveshell.py\", line 3269, in run_cell_async\n",
      "    has_raised = await self.run_ast_nodes(code_ast.body, cell_name,\n",
      "  File \"c:\\Users\\HP\\anaconda3\\envs\\ge\\Lib\\site-packages\\IPython\\core\\interactiveshell.py\", line 3448, in run_ast_nodes\n",
      "    if await self.run_code(code, result, async_=asy):\n",
      "  File \"c:\\Users\\HP\\anaconda3\\envs\\ge\\Lib\\site-packages\\IPython\\core\\interactiveshell.py\", line 3508, in run_code\n",
      "    exec(code_obj, self.user_global_ns, self.user_ns)\n",
      "  File \"C:\\Users\\HP\\AppData\\Local\\Temp\\ipykernel_17184\\2897584328.py\", line 13, in <module>\n",
      "    logger.info('hey')\n",
      "Message: 'hey'\n",
      "Arguments: ()\n",
      "--- Logging error ---\n",
      "Traceback (most recent call last):\n",
      "  File \"c:\\Users\\HP\\anaconda3\\envs\\ge\\Lib\\logging\\handlers.py\", line 74, in emit\n",
      "    self.doRollover()\n",
      "  File \"c:\\Users\\HP\\anaconda3\\envs\\ge\\Lib\\logging\\handlers.py\", line 435, in doRollover\n",
      "    self.rotate(self.baseFilename, dfn)\n",
      "  File \"c:\\Users\\HP\\anaconda3\\envs\\ge\\Lib\\logging\\handlers.py\", line 115, in rotate\n",
      "    os.rename(source, dest)\n",
      "PermissionError: [WinError 32] The process cannot access the file because it is being used by another process: 'd:\\\\full_stack\\\\MyPractice\\\\Python\\\\learning from youtube\\\\Intermediate\\\\logging\\\\timed_test.log' -> 'd:\\\\full_stack\\\\MyPractice\\\\Python\\\\learning from youtube\\\\Intermediate\\\\logging\\\\timed_test.log.2023-09-21_02-49-38'\n",
      "Call stack:\n",
      "  File \"<frozen runpy>\", line 198, in _run_module_as_main\n",
      "  File \"<frozen runpy>\", line 88, in _run_code\n",
      "  File \"c:\\Users\\HP\\anaconda3\\envs\\ge\\Lib\\site-packages\\ipykernel_launcher.py\", line 17, in <module>\n",
      "    app.launch_new_instance()\n",
      "  File \"c:\\Users\\HP\\anaconda3\\envs\\ge\\Lib\\site-packages\\traitlets\\config\\application.py\", line 1043, in launch_instance\n",
      "    app.start()\n",
      "  File \"c:\\Users\\HP\\anaconda3\\envs\\ge\\Lib\\site-packages\\ipykernel\\kernelapp.py\", line 712, in start\n",
      "    self.io_loop.start()\n",
      "  File \"c:\\Users\\HP\\anaconda3\\envs\\ge\\Lib\\site-packages\\tornado\\platform\\asyncio.py\", line 215, in start\n",
      "    self.asyncio_loop.run_forever()\n",
      "  File \"c:\\Users\\HP\\anaconda3\\envs\\ge\\Lib\\asyncio\\base_events.py\", line 607, in run_forever\n",
      "    self._run_once()\n",
      "  File \"c:\\Users\\HP\\anaconda3\\envs\\ge\\Lib\\asyncio\\base_events.py\", line 1922, in _run_once\n",
      "    handle._run()\n",
      "  File \"c:\\Users\\HP\\anaconda3\\envs\\ge\\Lib\\asyncio\\events.py\", line 80, in _run\n",
      "    self._context.run(self._callback, *self._args)\n",
      "  File \"c:\\Users\\HP\\anaconda3\\envs\\ge\\Lib\\site-packages\\ipykernel\\kernelbase.py\", line 510, in dispatch_queue\n",
      "    await self.process_one()\n",
      "  File \"c:\\Users\\HP\\anaconda3\\envs\\ge\\Lib\\site-packages\\ipykernel\\kernelbase.py\", line 499, in process_one\n",
      "    await dispatch(*args)\n",
      "  File \"c:\\Users\\HP\\anaconda3\\envs\\ge\\Lib\\site-packages\\ipykernel\\kernelbase.py\", line 406, in dispatch_shell\n",
      "    await result\n",
      "  File \"c:\\Users\\HP\\anaconda3\\envs\\ge\\Lib\\site-packages\\ipykernel\\kernelbase.py\", line 730, in execute_request\n",
      "    reply_content = await reply_content\n",
      "  File \"c:\\Users\\HP\\anaconda3\\envs\\ge\\Lib\\site-packages\\ipykernel\\ipkernel.py\", line 383, in do_execute\n",
      "    res = shell.run_cell(\n",
      "  File \"c:\\Users\\HP\\anaconda3\\envs\\ge\\Lib\\site-packages\\ipykernel\\zmqshell.py\", line 528, in run_cell\n",
      "    return super().run_cell(*args, **kwargs)\n",
      "  File \"c:\\Users\\HP\\anaconda3\\envs\\ge\\Lib\\site-packages\\IPython\\core\\interactiveshell.py\", line 3009, in run_cell\n",
      "    result = self._run_cell(\n",
      "  File \"c:\\Users\\HP\\anaconda3\\envs\\ge\\Lib\\site-packages\\IPython\\core\\interactiveshell.py\", line 3064, in _run_cell\n",
      "    result = runner(coro)\n",
      "  File \"c:\\Users\\HP\\anaconda3\\envs\\ge\\Lib\\site-packages\\IPython\\core\\async_helpers.py\", line 129, in _pseudo_sync_runner\n",
      "    coro.send(None)\n",
      "  File \"c:\\Users\\HP\\anaconda3\\envs\\ge\\Lib\\site-packages\\IPython\\core\\interactiveshell.py\", line 3269, in run_cell_async\n",
      "    has_raised = await self.run_ast_nodes(code_ast.body, cell_name,\n",
      "  File \"c:\\Users\\HP\\anaconda3\\envs\\ge\\Lib\\site-packages\\IPython\\core\\interactiveshell.py\", line 3448, in run_ast_nodes\n",
      "    if await self.run_code(code, result, async_=asy):\n",
      "  File \"c:\\Users\\HP\\anaconda3\\envs\\ge\\Lib\\site-packages\\IPython\\core\\interactiveshell.py\", line 3508, in run_code\n",
      "    exec(code_obj, self.user_global_ns, self.user_ns)\n",
      "  File \"C:\\Users\\HP\\AppData\\Local\\Temp\\ipykernel_17184\\2897584328.py\", line 13, in <module>\n",
      "    logger.info('hey')\n",
      "Message: 'hey'\n",
      "Arguments: ()\n",
      "--- Logging error ---\n",
      "Traceback (most recent call last):\n",
      "  File \"c:\\Users\\HP\\anaconda3\\envs\\ge\\Lib\\logging\\handlers.py\", line 74, in emit\n",
      "    self.doRollover()\n",
      "  File \"c:\\Users\\HP\\anaconda3\\envs\\ge\\Lib\\logging\\handlers.py\", line 435, in doRollover\n",
      "    self.rotate(self.baseFilename, dfn)\n",
      "  File \"c:\\Users\\HP\\anaconda3\\envs\\ge\\Lib\\logging\\handlers.py\", line 115, in rotate\n",
      "    os.rename(source, dest)\n",
      "PermissionError: [WinError 32] The process cannot access the file because it is being used by another process: 'd:\\\\full_stack\\\\MyPractice\\\\Python\\\\learning from youtube\\\\Intermediate\\\\logging\\\\timed_test.log' -> 'd:\\\\full_stack\\\\MyPractice\\\\Python\\\\learning from youtube\\\\Intermediate\\\\logging\\\\timed_test.log.2023-09-21_02-48-26'\n",
      "Call stack:\n",
      "  File \"<frozen runpy>\", line 198, in _run_module_as_main\n",
      "  File \"<frozen runpy>\", line 88, in _run_code\n",
      "  File \"c:\\Users\\HP\\anaconda3\\envs\\ge\\Lib\\site-packages\\ipykernel_launcher.py\", line 17, in <module>\n",
      "    app.launch_new_instance()\n",
      "  File \"c:\\Users\\HP\\anaconda3\\envs\\ge\\Lib\\site-packages\\traitlets\\config\\application.py\", line 1043, in launch_instance\n",
      "    app.start()\n",
      "  File \"c:\\Users\\HP\\anaconda3\\envs\\ge\\Lib\\site-packages\\ipykernel\\kernelapp.py\", line 712, in start\n",
      "    self.io_loop.start()\n",
      "  File \"c:\\Users\\HP\\anaconda3\\envs\\ge\\Lib\\site-packages\\tornado\\platform\\asyncio.py\", line 215, in start\n",
      "    self.asyncio_loop.run_forever()\n",
      "  File \"c:\\Users\\HP\\anaconda3\\envs\\ge\\Lib\\asyncio\\base_events.py\", line 607, in run_forever\n",
      "    self._run_once()\n",
      "  File \"c:\\Users\\HP\\anaconda3\\envs\\ge\\Lib\\asyncio\\base_events.py\", line 1922, in _run_once\n",
      "    handle._run()\n",
      "  File \"c:\\Users\\HP\\anaconda3\\envs\\ge\\Lib\\asyncio\\events.py\", line 80, in _run\n",
      "    self._context.run(self._callback, *self._args)\n",
      "  File \"c:\\Users\\HP\\anaconda3\\envs\\ge\\Lib\\site-packages\\ipykernel\\kernelbase.py\", line 510, in dispatch_queue\n",
      "    await self.process_one()\n",
      "  File \"c:\\Users\\HP\\anaconda3\\envs\\ge\\Lib\\site-packages\\ipykernel\\kernelbase.py\", line 499, in process_one\n",
      "    await dispatch(*args)\n",
      "  File \"c:\\Users\\HP\\anaconda3\\envs\\ge\\Lib\\site-packages\\ipykernel\\kernelbase.py\", line 406, in dispatch_shell\n",
      "    await result\n",
      "  File \"c:\\Users\\HP\\anaconda3\\envs\\ge\\Lib\\site-packages\\ipykernel\\kernelbase.py\", line 730, in execute_request\n",
      "    reply_content = await reply_content\n",
      "  File \"c:\\Users\\HP\\anaconda3\\envs\\ge\\Lib\\site-packages\\ipykernel\\ipkernel.py\", line 383, in do_execute\n",
      "    res = shell.run_cell(\n",
      "  File \"c:\\Users\\HP\\anaconda3\\envs\\ge\\Lib\\site-packages\\ipykernel\\zmqshell.py\", line 528, in run_cell\n",
      "    return super().run_cell(*args, **kwargs)\n",
      "  File \"c:\\Users\\HP\\anaconda3\\envs\\ge\\Lib\\site-packages\\IPython\\core\\interactiveshell.py\", line 3009, in run_cell\n",
      "    result = self._run_cell(\n",
      "  File \"c:\\Users\\HP\\anaconda3\\envs\\ge\\Lib\\site-packages\\IPython\\core\\interactiveshell.py\", line 3064, in _run_cell\n",
      "    result = runner(coro)\n",
      "  File \"c:\\Users\\HP\\anaconda3\\envs\\ge\\Lib\\site-packages\\IPython\\core\\async_helpers.py\", line 129, in _pseudo_sync_runner\n",
      "    coro.send(None)\n",
      "  File \"c:\\Users\\HP\\anaconda3\\envs\\ge\\Lib\\site-packages\\IPython\\core\\interactiveshell.py\", line 3269, in run_cell_async\n",
      "    has_raised = await self.run_ast_nodes(code_ast.body, cell_name,\n",
      "  File \"c:\\Users\\HP\\anaconda3\\envs\\ge\\Lib\\site-packages\\IPython\\core\\interactiveshell.py\", line 3448, in run_ast_nodes\n",
      "    if await self.run_code(code, result, async_=asy):\n",
      "  File \"c:\\Users\\HP\\anaconda3\\envs\\ge\\Lib\\site-packages\\IPython\\core\\interactiveshell.py\", line 3508, in run_code\n",
      "    exec(code_obj, self.user_global_ns, self.user_ns)\n",
      "  File \"C:\\Users\\HP\\AppData\\Local\\Temp\\ipykernel_17184\\2897584328.py\", line 13, in <module>\n",
      "    logger.info('hey')\n",
      "Message: 'hey'\n",
      "Arguments: ()\n",
      "--- Logging error ---\n",
      "Traceback (most recent call last):\n",
      "  File \"c:\\Users\\HP\\anaconda3\\envs\\ge\\Lib\\logging\\handlers.py\", line 74, in emit\n",
      "    self.doRollover()\n",
      "  File \"c:\\Users\\HP\\anaconda3\\envs\\ge\\Lib\\logging\\handlers.py\", line 435, in doRollover\n",
      "    self.rotate(self.baseFilename, dfn)\n",
      "  File \"c:\\Users\\HP\\anaconda3\\envs\\ge\\Lib\\logging\\handlers.py\", line 115, in rotate\n",
      "    os.rename(source, dest)\n",
      "PermissionError: [WinError 32] The process cannot access the file because it is being used by another process: 'd:\\\\full_stack\\\\MyPractice\\\\Python\\\\learning from youtube\\\\Intermediate\\\\logging\\\\timed_test.log' -> 'd:\\\\full_stack\\\\MyPractice\\\\Python\\\\learning from youtube\\\\Intermediate\\\\logging\\\\timed_test.log.2023-09-21_02-49-38'\n",
      "Call stack:\n",
      "  File \"<frozen runpy>\", line 198, in _run_module_as_main\n",
      "  File \"<frozen runpy>\", line 88, in _run_code\n",
      "  File \"c:\\Users\\HP\\anaconda3\\envs\\ge\\Lib\\site-packages\\ipykernel_launcher.py\", line 17, in <module>\n",
      "    app.launch_new_instance()\n",
      "  File \"c:\\Users\\HP\\anaconda3\\envs\\ge\\Lib\\site-packages\\traitlets\\config\\application.py\", line 1043, in launch_instance\n",
      "    app.start()\n",
      "  File \"c:\\Users\\HP\\anaconda3\\envs\\ge\\Lib\\site-packages\\ipykernel\\kernelapp.py\", line 712, in start\n",
      "    self.io_loop.start()\n",
      "  File \"c:\\Users\\HP\\anaconda3\\envs\\ge\\Lib\\site-packages\\tornado\\platform\\asyncio.py\", line 215, in start\n",
      "    self.asyncio_loop.run_forever()\n",
      "  File \"c:\\Users\\HP\\anaconda3\\envs\\ge\\Lib\\asyncio\\base_events.py\", line 607, in run_forever\n",
      "    self._run_once()\n",
      "  File \"c:\\Users\\HP\\anaconda3\\envs\\ge\\Lib\\asyncio\\base_events.py\", line 1922, in _run_once\n",
      "    handle._run()\n",
      "  File \"c:\\Users\\HP\\anaconda3\\envs\\ge\\Lib\\asyncio\\events.py\", line 80, in _run\n",
      "    self._context.run(self._callback, *self._args)\n",
      "  File \"c:\\Users\\HP\\anaconda3\\envs\\ge\\Lib\\site-packages\\ipykernel\\kernelbase.py\", line 510, in dispatch_queue\n",
      "    await self.process_one()\n",
      "  File \"c:\\Users\\HP\\anaconda3\\envs\\ge\\Lib\\site-packages\\ipykernel\\kernelbase.py\", line 499, in process_one\n",
      "    await dispatch(*args)\n",
      "  File \"c:\\Users\\HP\\anaconda3\\envs\\ge\\Lib\\site-packages\\ipykernel\\kernelbase.py\", line 406, in dispatch_shell\n",
      "    await result\n",
      "  File \"c:\\Users\\HP\\anaconda3\\envs\\ge\\Lib\\site-packages\\ipykernel\\kernelbase.py\", line 730, in execute_request\n",
      "    reply_content = await reply_content\n",
      "  File \"c:\\Users\\HP\\anaconda3\\envs\\ge\\Lib\\site-packages\\ipykernel\\ipkernel.py\", line 383, in do_execute\n",
      "    res = shell.run_cell(\n",
      "  File \"c:\\Users\\HP\\anaconda3\\envs\\ge\\Lib\\site-packages\\ipykernel\\zmqshell.py\", line 528, in run_cell\n",
      "    return super().run_cell(*args, **kwargs)\n",
      "  File \"c:\\Users\\HP\\anaconda3\\envs\\ge\\Lib\\site-packages\\IPython\\core\\interactiveshell.py\", line 3009, in run_cell\n",
      "    result = self._run_cell(\n",
      "  File \"c:\\Users\\HP\\anaconda3\\envs\\ge\\Lib\\site-packages\\IPython\\core\\interactiveshell.py\", line 3064, in _run_cell\n",
      "    result = runner(coro)\n",
      "  File \"c:\\Users\\HP\\anaconda3\\envs\\ge\\Lib\\site-packages\\IPython\\core\\async_helpers.py\", line 129, in _pseudo_sync_runner\n",
      "    coro.send(None)\n",
      "  File \"c:\\Users\\HP\\anaconda3\\envs\\ge\\Lib\\site-packages\\IPython\\core\\interactiveshell.py\", line 3269, in run_cell_async\n",
      "    has_raised = await self.run_ast_nodes(code_ast.body, cell_name,\n",
      "  File \"c:\\Users\\HP\\anaconda3\\envs\\ge\\Lib\\site-packages\\IPython\\core\\interactiveshell.py\", line 3448, in run_ast_nodes\n",
      "    if await self.run_code(code, result, async_=asy):\n",
      "  File \"c:\\Users\\HP\\anaconda3\\envs\\ge\\Lib\\site-packages\\IPython\\core\\interactiveshell.py\", line 3508, in run_code\n",
      "    exec(code_obj, self.user_global_ns, self.user_ns)\n",
      "  File \"C:\\Users\\HP\\AppData\\Local\\Temp\\ipykernel_17184\\2897584328.py\", line 13, in <module>\n",
      "    logger.info('hey')\n",
      "Message: 'hey'\n",
      "Arguments: ()\n",
      "--- Logging error ---\n",
      "Traceback (most recent call last):\n",
      "  File \"c:\\Users\\HP\\anaconda3\\envs\\ge\\Lib\\logging\\handlers.py\", line 74, in emit\n",
      "    self.doRollover()\n",
      "  File \"c:\\Users\\HP\\anaconda3\\envs\\ge\\Lib\\logging\\handlers.py\", line 435, in doRollover\n",
      "    self.rotate(self.baseFilename, dfn)\n",
      "  File \"c:\\Users\\HP\\anaconda3\\envs\\ge\\Lib\\logging\\handlers.py\", line 115, in rotate\n",
      "    os.rename(source, dest)\n",
      "PermissionError: [WinError 32] The process cannot access the file because it is being used by another process: 'd:\\\\full_stack\\\\MyPractice\\\\Python\\\\learning from youtube\\\\Intermediate\\\\logging\\\\timed_test.log' -> 'd:\\\\full_stack\\\\MyPractice\\\\Python\\\\learning from youtube\\\\Intermediate\\\\logging\\\\timed_test.log.2023-09-21_02-48-26'\n",
      "Call stack:\n",
      "  File \"<frozen runpy>\", line 198, in _run_module_as_main\n",
      "  File \"<frozen runpy>\", line 88, in _run_code\n",
      "  File \"c:\\Users\\HP\\anaconda3\\envs\\ge\\Lib\\site-packages\\ipykernel_launcher.py\", line 17, in <module>\n",
      "    app.launch_new_instance()\n",
      "  File \"c:\\Users\\HP\\anaconda3\\envs\\ge\\Lib\\site-packages\\traitlets\\config\\application.py\", line 1043, in launch_instance\n",
      "    app.start()\n",
      "  File \"c:\\Users\\HP\\anaconda3\\envs\\ge\\Lib\\site-packages\\ipykernel\\kernelapp.py\", line 712, in start\n",
      "    self.io_loop.start()\n",
      "  File \"c:\\Users\\HP\\anaconda3\\envs\\ge\\Lib\\site-packages\\tornado\\platform\\asyncio.py\", line 215, in start\n",
      "    self.asyncio_loop.run_forever()\n",
      "  File \"c:\\Users\\HP\\anaconda3\\envs\\ge\\Lib\\asyncio\\base_events.py\", line 607, in run_forever\n",
      "    self._run_once()\n",
      "  File \"c:\\Users\\HP\\anaconda3\\envs\\ge\\Lib\\asyncio\\base_events.py\", line 1922, in _run_once\n",
      "    handle._run()\n",
      "  File \"c:\\Users\\HP\\anaconda3\\envs\\ge\\Lib\\asyncio\\events.py\", line 80, in _run\n",
      "    self._context.run(self._callback, *self._args)\n",
      "  File \"c:\\Users\\HP\\anaconda3\\envs\\ge\\Lib\\site-packages\\ipykernel\\kernelbase.py\", line 510, in dispatch_queue\n",
      "    await self.process_one()\n",
      "  File \"c:\\Users\\HP\\anaconda3\\envs\\ge\\Lib\\site-packages\\ipykernel\\kernelbase.py\", line 499, in process_one\n",
      "    await dispatch(*args)\n",
      "  File \"c:\\Users\\HP\\anaconda3\\envs\\ge\\Lib\\site-packages\\ipykernel\\kernelbase.py\", line 406, in dispatch_shell\n",
      "    await result\n",
      "  File \"c:\\Users\\HP\\anaconda3\\envs\\ge\\Lib\\site-packages\\ipykernel\\kernelbase.py\", line 730, in execute_request\n",
      "    reply_content = await reply_content\n",
      "  File \"c:\\Users\\HP\\anaconda3\\envs\\ge\\Lib\\site-packages\\ipykernel\\ipkernel.py\", line 383, in do_execute\n",
      "    res = shell.run_cell(\n",
      "  File \"c:\\Users\\HP\\anaconda3\\envs\\ge\\Lib\\site-packages\\ipykernel\\zmqshell.py\", line 528, in run_cell\n",
      "    return super().run_cell(*args, **kwargs)\n",
      "  File \"c:\\Users\\HP\\anaconda3\\envs\\ge\\Lib\\site-packages\\IPython\\core\\interactiveshell.py\", line 3009, in run_cell\n",
      "    result = self._run_cell(\n",
      "  File \"c:\\Users\\HP\\anaconda3\\envs\\ge\\Lib\\site-packages\\IPython\\core\\interactiveshell.py\", line 3064, in _run_cell\n",
      "    result = runner(coro)\n",
      "  File \"c:\\Users\\HP\\anaconda3\\envs\\ge\\Lib\\site-packages\\IPython\\core\\async_helpers.py\", line 129, in _pseudo_sync_runner\n",
      "    coro.send(None)\n",
      "  File \"c:\\Users\\HP\\anaconda3\\envs\\ge\\Lib\\site-packages\\IPython\\core\\interactiveshell.py\", line 3269, in run_cell_async\n",
      "    has_raised = await self.run_ast_nodes(code_ast.body, cell_name,\n",
      "  File \"c:\\Users\\HP\\anaconda3\\envs\\ge\\Lib\\site-packages\\IPython\\core\\interactiveshell.py\", line 3448, in run_ast_nodes\n",
      "    if await self.run_code(code, result, async_=asy):\n",
      "  File \"c:\\Users\\HP\\anaconda3\\envs\\ge\\Lib\\site-packages\\IPython\\core\\interactiveshell.py\", line 3508, in run_code\n",
      "    exec(code_obj, self.user_global_ns, self.user_ns)\n",
      "  File \"C:\\Users\\HP\\AppData\\Local\\Temp\\ipykernel_17184\\2897584328.py\", line 13, in <module>\n",
      "    logger.info('hey')\n",
      "Message: 'hey'\n",
      "Arguments: ()\n",
      "--- Logging error ---\n",
      "Traceback (most recent call last):\n",
      "  File \"c:\\Users\\HP\\anaconda3\\envs\\ge\\Lib\\logging\\handlers.py\", line 74, in emit\n",
      "    self.doRollover()\n",
      "  File \"c:\\Users\\HP\\anaconda3\\envs\\ge\\Lib\\logging\\handlers.py\", line 435, in doRollover\n",
      "    self.rotate(self.baseFilename, dfn)\n",
      "  File \"c:\\Users\\HP\\anaconda3\\envs\\ge\\Lib\\logging\\handlers.py\", line 115, in rotate\n",
      "    os.rename(source, dest)\n",
      "PermissionError: [WinError 32] The process cannot access the file because it is being used by another process: 'd:\\\\full_stack\\\\MyPractice\\\\Python\\\\learning from youtube\\\\Intermediate\\\\logging\\\\timed_test.log' -> 'd:\\\\full_stack\\\\MyPractice\\\\Python\\\\learning from youtube\\\\Intermediate\\\\logging\\\\timed_test.log.2023-09-21_02-49-38'\n",
      "Call stack:\n",
      "  File \"<frozen runpy>\", line 198, in _run_module_as_main\n",
      "  File \"<frozen runpy>\", line 88, in _run_code\n",
      "  File \"c:\\Users\\HP\\anaconda3\\envs\\ge\\Lib\\site-packages\\ipykernel_launcher.py\", line 17, in <module>\n",
      "    app.launch_new_instance()\n",
      "  File \"c:\\Users\\HP\\anaconda3\\envs\\ge\\Lib\\site-packages\\traitlets\\config\\application.py\", line 1043, in launch_instance\n",
      "    app.start()\n",
      "  File \"c:\\Users\\HP\\anaconda3\\envs\\ge\\Lib\\site-packages\\ipykernel\\kernelapp.py\", line 712, in start\n",
      "    self.io_loop.start()\n",
      "  File \"c:\\Users\\HP\\anaconda3\\envs\\ge\\Lib\\site-packages\\tornado\\platform\\asyncio.py\", line 215, in start\n",
      "    self.asyncio_loop.run_forever()\n",
      "  File \"c:\\Users\\HP\\anaconda3\\envs\\ge\\Lib\\asyncio\\base_events.py\", line 607, in run_forever\n",
      "    self._run_once()\n",
      "  File \"c:\\Users\\HP\\anaconda3\\envs\\ge\\Lib\\asyncio\\base_events.py\", line 1922, in _run_once\n",
      "    handle._run()\n",
      "  File \"c:\\Users\\HP\\anaconda3\\envs\\ge\\Lib\\asyncio\\events.py\", line 80, in _run\n",
      "    self._context.run(self._callback, *self._args)\n",
      "  File \"c:\\Users\\HP\\anaconda3\\envs\\ge\\Lib\\site-packages\\ipykernel\\kernelbase.py\", line 510, in dispatch_queue\n",
      "    await self.process_one()\n",
      "  File \"c:\\Users\\HP\\anaconda3\\envs\\ge\\Lib\\site-packages\\ipykernel\\kernelbase.py\", line 499, in process_one\n",
      "    await dispatch(*args)\n",
      "  File \"c:\\Users\\HP\\anaconda3\\envs\\ge\\Lib\\site-packages\\ipykernel\\kernelbase.py\", line 406, in dispatch_shell\n",
      "    await result\n",
      "  File \"c:\\Users\\HP\\anaconda3\\envs\\ge\\Lib\\site-packages\\ipykernel\\kernelbase.py\", line 730, in execute_request\n",
      "    reply_content = await reply_content\n",
      "  File \"c:\\Users\\HP\\anaconda3\\envs\\ge\\Lib\\site-packages\\ipykernel\\ipkernel.py\", line 383, in do_execute\n",
      "    res = shell.run_cell(\n",
      "  File \"c:\\Users\\HP\\anaconda3\\envs\\ge\\Lib\\site-packages\\ipykernel\\zmqshell.py\", line 528, in run_cell\n",
      "    return super().run_cell(*args, **kwargs)\n",
      "  File \"c:\\Users\\HP\\anaconda3\\envs\\ge\\Lib\\site-packages\\IPython\\core\\interactiveshell.py\", line 3009, in run_cell\n",
      "    result = self._run_cell(\n",
      "  File \"c:\\Users\\HP\\anaconda3\\envs\\ge\\Lib\\site-packages\\IPython\\core\\interactiveshell.py\", line 3064, in _run_cell\n",
      "    result = runner(coro)\n",
      "  File \"c:\\Users\\HP\\anaconda3\\envs\\ge\\Lib\\site-packages\\IPython\\core\\async_helpers.py\", line 129, in _pseudo_sync_runner\n",
      "    coro.send(None)\n",
      "  File \"c:\\Users\\HP\\anaconda3\\envs\\ge\\Lib\\site-packages\\IPython\\core\\interactiveshell.py\", line 3269, in run_cell_async\n",
      "    has_raised = await self.run_ast_nodes(code_ast.body, cell_name,\n",
      "  File \"c:\\Users\\HP\\anaconda3\\envs\\ge\\Lib\\site-packages\\IPython\\core\\interactiveshell.py\", line 3448, in run_ast_nodes\n",
      "    if await self.run_code(code, result, async_=asy):\n",
      "  File \"c:\\Users\\HP\\anaconda3\\envs\\ge\\Lib\\site-packages\\IPython\\core\\interactiveshell.py\", line 3508, in run_code\n",
      "    exec(code_obj, self.user_global_ns, self.user_ns)\n",
      "  File \"C:\\Users\\HP\\AppData\\Local\\Temp\\ipykernel_17184\\2897584328.py\", line 13, in <module>\n",
      "    logger.info('hey')\n",
      "Message: 'hey'\n",
      "Arguments: ()\n"
     ]
    }
   ],
   "source": [
    "import logging\n",
    "import time\n",
    "from logging.handlers import TimedRotatingFileHandler\n",
    " \n",
    "logger = logging.getLogger(__name__)\n",
    "logger.setLevel(logging.INFO)\n",
    "\n",
    "# This will create a new log file every minute, and 5 backup files with a timestamp before overwriting old logs.\n",
    "handler = TimedRotatingFileHandler('timed_test.log', when='s', interval=5, backupCount=5)\n",
    "logger.addHandler(handler)\n",
    " \n",
    "for i in range(6):\n",
    "    logger.info('hey')\n",
    "    time.sleep(2)"
   ]
  },
  {
   "cell_type": "markdown",
   "metadata": {},
   "source": [
    "## Logging in JSON Format\n",
    "If your application generates many logs from different modules, and especially in a microservice architecture, it can be challenging to locate the important logs for your analysis. Therefore, it is best practice to log your messages in JSON format, and send them to a centralized log management system. Then you can easily search, visualize, and analyze your log records.\n",
    "I would recommend using this Open Source JSON logger: https://github.com/madzak/python-json-logger\n",
    "`pip install python-json-logger`"
   ]
  },
  {
   "cell_type": "code",
   "execution_count": null,
   "metadata": {},
   "outputs": [],
   "source": [
    "import logging\n",
    "from pythonjsonlogger import jsonlogger\n",
    "\n",
    "logger = logging.getLogger()\n",
    "\n",
    "logHandler = logging.StreamHandler()\n",
    "formatter = jsonlogger.JsonFormatter()\n",
    "logHandler.setFormatter(formatter)\n",
    "logger.addHandler(logHandler)"
   ]
  },
  {
   "cell_type": "code",
   "execution_count": null,
   "metadata": {},
   "outputs": [],
   "source": []
  }
 ],
 "metadata": {
  "kernelspec": {
   "display_name": "ge",
   "language": "python",
   "name": "python3"
  },
  "language_info": {
   "codemirror_mode": {
    "name": "ipython",
    "version": 3
   },
   "file_extension": ".py",
   "mimetype": "text/x-python",
   "name": "python",
   "nbconvert_exporter": "python",
   "pygments_lexer": "ipython3",
   "version": "3.11.4"
  },
  "orig_nbformat": 4
 },
 "nbformat": 4,
 "nbformat_minor": 2
}
